<mujoco>
   <compiler 	meshdir="Meshes/" 
	    coordinate="local" 
		angle="radian"/>
   <option gravity="0 0 0"/>
   <worldbody>
        <light diffuse=".5 .5 .5" pos="0 0 3" dir="0 0 -1"/>    
        <geom type="plane" size="1 1 0.1" rgba=".9 0 0 1"/>

        <body name="table" pos="0 0 0" quat="1 0.4 0.4 1">
            <inertial pos="0 0 0" mass="100.0" diaginertia="1.0 1.0 1.0"/>
            <geom name="table_geom" type="box" pos="0 0 0.42" size="0.25 1.0 0.05" contype="1"
            conaffinity="1"/>
             <body pos="0 0.75 1">
                <joint type="slide" axis="0 1 0" damping="-80" />
                <joint type="slide" axis="0 0 1" damping="-10"/>
                 <geom type="box" size=".1 .2 .3" rgba="0 .9 0 1" conaffinity="0" contype="1"/>
            </body>
        </body>
        <body pos="0 0 1.5">
        <site name="cg" pos="0 0 0" size="0.05"/>
        <joint type="free"/>
        <geom type="box" size=".1 .2 .3" rgba="0 .9 1 1" conaffinity="0" contype="1"/>
       </body>
   </worldbody>
<actuator>
    <general site="cg" gear="0 0 1 0 0 0" dynprm="0 0 0" gainprm="0 0 0" biastype="affine" biasprm="-9.81 0 0"/>
</actuator>
</mujoco>
