<!-- Reacher Model

    State-Space (name/joint/parameter):
        - shoulder      hinge       angle (rad)
        - target_x      slider      position x (m)
        - target_y      slider      position x (m)
        - shoulder      hinge       angular velocity (rad/s)
        - target_x      slider      velocity x (m/s)
        - target_y      slider      velocity x (m/s)

    Actuators (name/joint/parameter):
        - shoulder      motor       force x (N)

-->
<mujoco model='reacher'>
    <compiler inertiafromgeom='true' coordinate='local' angle='degree' />

    <default>
        <joint islimited='true' damping='.003' compliance='1e-2'
               timeconst='3e-3' stiffness='0'/>
        <geom mindist='.1' compliance='7e-2' timeconst='1e-2' contype='1'
              conaffinity='1' condim='3' friction='.7 .1 .1'
              rgba='0.8 0.6 .4 1'/>
        <act-motor ctrlrange='-1 1' isctrllimited='true'/>
    </default>

    <size nstack='300000' ngeom_user='1'/>

    <option timestep='0.007' gravity='0 0 0'>
        <disable warmstart='true'/>
    </option>

    <body>
        <!-- Arena -->
        <geom name='ground' type='plane' pos='0 0 0' size='1 1 10'
              rgba='0.9 0.9 0.9 1' conaffinity='0' contype='0'/>
        <geom name='sideS' type='capsule' fromto='-.3 -.3 .01 .3 -.3 .01'
              size='.02' rgba='0.9 0.4 0.6 1' conaffinity='0'/>
        <geom name='sideE' type='capsule' fromto=' .3 -.3 .01 .3  .3 .01'
              size='.02' rgba='0.9 0.4 0.6 1' conaffinity='0'/>
        <geom name='sideN' type='capsule' fromto='-.3  .3 .01 .3  .3 .01'
              size='.02' rgba='0.9 0.4 0.6 1' conaffinity='0'/>
        <geom name='sideW' type='capsule' fromto='-.3 -.3 .01 -.3 .3 .01'
              size='.02' rgba='0.9 0.4 0.6 1' conaffinity='0'/>

        <!-- Arm -->
        <geom name='root' type='cylinder' fromto='0 0 0 0 0 0.02' size='.011'
              rgba='0.9 0.4 0.6 1' contype='0' conaffinity='0'/>
        <body name='uarm' pos='0 0 .01'>
            <geom name='uarm' type='capsule' fromto='0 0 0 0.1 0 0' size='.01'
                  rgba='0.0 0.4 0.6 1'/>
            <joint name='shoulder' islimited='false' type='hinge' pos='0 0 0'
                   axis='0 0 1'/>
            <geom name='finger' type='sphere' pos='0.12 0 0' size='.006'
                  rgba='0.0 0.8 0.6 1' contype='0'/>
        </body>

        <!-- Target -->
        <body name='target' pos='.1 -.1 .01'>
            <joint name='target_x' type='slide' pos='0 0 0' axis='1 0 0'
                   islimited='true' range='-.27 .27' damping='0' armature='0'
                   stiffness='0' ref='.1'/>
            <joint name='target_y' type='slide' pos='0 0 0' axis='0 1 0'
                   islimited='true' range='-.27 .27' damping='0' armature='0'
                   stiffness='0' ref='-.1'/>
            <geom name='target' pos='0 0 0' rgba='0.9 0.2 0.2 1' contype='0'
                  conaffinity='0' type='sphere' size='.009'/>
        </body>

    </body>

    <actuator>
        <motor joint='shoulder' gear='.1'/>
    </actuator>


    <textfield>
        <text name='cost' data='features.xml'/>
    </textfield>

</mujoco>
