<mujoco model="arm3d">
  <compiler inertiafromgeom="true" angle="degree" coordinate="local"/>
  <option timestep="0.01" eqsoft="true" remotecontact="true" gravity="0 0 0" iterations='20'/>
  <!-- s_armature='.1 10' -->
  <default>
    <!--<joint islimited="false" damping="10" maxvel="12" armature='0.5' frictionloss='0.1' isfrictional='true' makeactuator="true"/>-->
    <joint islimited="false" damping="1" makeactuator="true"/>
    <geom contype="2" conaffinity="1" condim="1" friction=".5 .1 .1"
          density="1000" mindist="0.002" compliance="0.001"
          timeconst="0.01"/>
    <!-- Note for later: what made the insertion easy was changing mindist and compliance to 0.002/0.001 and enabling remotecontact -->
  </default>

  <body>
    <body name="shoulder" pos="0 0 1.5">
      <geom name="shoulder_geom" type="capsule" fromto="0 0 0 0 0 -1" size="0.05"/>
      <joint name="shoulder_rot1" type="hinge" pos="0 0 0" axis="0 0 1"/>
      <joint name="shoulder_rot2" type="hinge" pos="0 0 0" axis="0 1 0"/>
      <joint name="shoulder_rot3" type="hinge" pos="0 0 0" axis="1 0 0"/>

      <body name="forearm" pos="0 0 -1">
        <geom name="forearm_geom" type="capsule" fromto="0 0 0 0 0 -1" size="0.05"/>
        <joint name="forearm_rot" type="hinge" pos="0 0 0" axis="1 0 0"/>

        <body name="finger" pos="0 0 -1">
          <geom name="finger_geom" type="capsule" pos="0 0 0" fromto="0 0 0 0 0 -0.5" size="0.025"/>
          <geom name="finger_tip" type="sphere" pos="0 0 -0.5" size="0.025" density="1"/>
          <site name="finger_tip_site" pos="0 0 -0.5"/>
          <joint name="finger_rot1" type="hinge" pos="0 0 0" axis="1 0 0"/>
          <joint name="finger_rot2" type="hinge" pos="0 0 0" axis="0 1 0"/>
        </body>
      </body>
    </body>

    <!--
    <geom name='floor' pos='0 0 0' size='40 40 40' type='plane' contype='1'  rgba='0.8 0.9 0.8 1' condim='3'/>
    -->

    <body name="w1" pos="0 -0.53 -0.5">
      <geom name="wall1" type="box" size="1.03 0.5 0.5" contype="1"/>
    </body>
    <body name="w2" pos="0 0.53 -0.5">
      <geom name="wall2" type="box" size="1.03 0.5 0.5" contype="1"/>
    </body>
    <body name="w3" pos="0.53 0 -0.5">
      <geom name="wall3" type="box" size="0.5 0.03 0.5" contype="1"/>
    </body>
    <body name="w4" pos="-0.53 0 -0.5">
      <geom name="wall4" type="box" size="0.5 0.03 0.5" contype="1"/>
    </body>

    <body name="w5" pos="0 0 -0.75">
      <geom name="wall5" type="box" size="0.03 0.03 0.25" contype="1"/>
    </body>

  </body>

  <features>
    <feature name='control'>
      <data field='ctrl' item='all'/>
    </feature>
  </features>
  <costs>

    <physics_options  timestep='0.01'/>

    <optimization_options
        logeps='-30'
        horizon='400'
        logmurange='-5 3'
        />

    <cost name='dummy'>
      <term feature='control'       norm='quadratic'    coef_running='.1' />
    </cost>
  </costs>
</mujoco>
