<?xml version="1.0" ?><!-- ======================================================
	This file is part of MuJoCo.
	Copyright 2009-2015 Roboti LLC.

	Model 		:: PR2 from Willow Garage
		Source		: (Provided by Sergey Levine, UC Berkeley)
		Downloaded	: 18July'14

	Mujoco		:: Advanced physics simulation engine
		Source		: www.roboti.us
		Version		: 1.22
		Released 	: 26Nov15

	Author		:: Vikash Kumar
		Contacts 	: kumar@roboti.us
		Last edits 	: 14Dec'15, 10Oct'15
====================================================== --><mujoco model="pr2(v1.22)">
    <compiler angle="radian" coordinate="local" meshdir="Meshes/"/>

	<option collision="all" gravity="0 0 0" timestep="0.05"/>
	<asset>
		<mesh file="base_L.stl"/>
		<mesh file="caster_L.stl"/>
		<mesh file="torso_lift_L.stl"/>
		<mesh file="head_pan_L.stl"/>
		<mesh file="head_tilt_L.stl"/>
		<mesh file="tilting_hokuyo_L.stl"/>
		<mesh file="shoulder_pan.stl"/>
		<mesh file="shoulder_lift.stl"/>
		<mesh file="upper_arm_roll_L.stl"/>
		<mesh file="upper_arm.stl"/>
		<mesh file="elbow_flex.stl"/>
		<mesh file="forearm_roll_L.stl"/>
		<mesh file="forearm.stl"/>


		<mesh file="wrist_flex.stl"/>
		<mesh file="wrist_roll_L.stl"/>
		<mesh file="gripper_palm.stl"/>
		<mesh file="l_finger.stl"/>
		<mesh file="l_finger_tip.stl"/>

		<material name="MatGnd" reflectance="0.3" rgba=".5 .55 .5 1" shininess=".3" specular=".3"/>
	</asset>



    <contact>
        <pair geom1="r_gripper_l_finger_tip" geom2="r_gripper_r_finger_tip"/>
		<pair geom1="l_gripper_l_finger_tip" geom2="l_gripper_r_finger_tip"/>
		<pair geom1="base" geom2="r_forearm"/>
		<pair geom1="base" geom2="l_forearm"/>

    </contact>

    <default>
        <joint armature=".005" damping=".01" frictional="false" limited="false"/>
        <geom conaffinity="0" contype="1" friction="1 0.1 0.1" type="mesh"/>
		<default class="gripper">
			<joint armature=".005" damping="0.005"/>
		</default>
    </default>

    <worldbody>
	<light cutoff="4" diffuse="1 1 1" dir="-.5 -0.75 -1.5" directional="true" exponent="20" pos=".5 0.75 1.5" specular="0 0 0"/>
	<geom conaffinity="1" contype="0" material="MatGnd" name="gnd" pos="0 0 0" size="1.5 1.5 0.25" type="plane"/>

        <body name="base_footprint" pos="0 0 0">

            <inertial diaginertia="0.01 0.01 0.01" mass="1" pos="0 0 0"/>
            <!--<geom name="geom0" type="box" pos="0 0 0.071" size="0.005 0.005 0.005" rgba="1 0 0 1" group="2" />-->
            <body name="base_link" pos="0 0 0.051">
                <inertial diaginertia="6.293885 5.669245 3.041772" mass="116" pos="-0.061 0 0.293" quat="0.973598 0.001764 -0.228065 -0.009443"/>
                <geom contype="0" mesh="base_L" name="base" rgba="1 1 1 1"/>

                <body name="torso_lift_link" pos="-0.05 0 0.739675">
                    <inertial diaginertia="2.783075 2.510450 0.514581" mass="36.248046" pos="-0.1 0 -0.0885" quat="0.999335 0.007626 0.035453 0.003712"/>
                    <!--<joint name="torso_lift_joint" type="slide" pos="0 0 0" axis="0 0 1" limited="true" range="0 0.31"/>-->
                    <geom contype="0" mesh="torso_lift_L" name="geom15" rgba="0.9 0.9 0.9 1"/>

                    <body name="l_shoulder_pan_link" pos="0 0.188 0">
                        <inertial diaginertia="0.934201 0.837701 0.242033" mass="25.799322" pos="-0.001201 0.024513 -0.098231" quat="0.927482 -0.087656 0.074060 -0.355821"/>
                        <joint armature="0.100000182524" axis="0 0 1" damping="10.0000047184" frictional="true" frictionloss="0.100000047222" limited="true" name="l_shoulder_pan_joint" pos="0 0 0" range="-0.714602 2.285398" stiffness="1.00000035799" type="hinge"/>
                        <geom contype="0" mesh="shoulder_pan" name="geom50" rgba="0.7 0.7 0.7 1"/>

                        <!--geom name="geom50f" type="box" pos="0.01642114 0.00171030 -0.18118357" size="0.18 0.13 0.32589236" rgba="0 0 0.8 1" group="1"/-->

                        <body name="l_shoulder_lift_link" pos="0.1 0 0">
                            <inertial diaginertia="0.026187 0.020730 0.015168" mass="2.74988" pos="0.02195 -0.02664 -0.03127" quat="0.791779 0.478014 0.238985 0.295762"/>
                            <joint armature="0.10000105743" axis="0 1 0" damping="10.0000018222" frictional="true" frictionloss="1.00000002821" limited="true" name="l_shoulder_lift_joint" pos="0 0 0" range="-0.5236 1.3963" stiffness="1.00000015183" type="hinge"/>
                            <geom mesh="shoulder_lift" name="geom51" rgba="0.7 0.7 0.7 1"/>
                            <body name="l_upper_arm_roll_link" pos="0 0 0">
                                <inertial diaginertia="0.01 0.01 0.01" mass="0.1" pos="0 0 0"/>
                                <!--joint name="l_upper_arm_roll_joint" type="hinge" pos="0 0 0" axis="1 0 0" limited="true" range="-0.8 3.9"/-->
                                <joint armature="0.100000531932" axis="1 0 0" damping="0.100000959651" frictional="true" frictionloss="1.00000003037" limited="true" name="l_upper_arm_roll_joint" pos="0 0 0" range="-0.8 3.9" stiffness="1.00000001671" type="hinge"/>
                                <!--mesh name="geom52" mesh="upper_arm_roll_L" /-->
                                <body name="l_upper_arm_link" pos="0 0 0">
                                    <inertial diaginertia="0.076070 0.074882 0.015107" mass="6.01769" pos="0.21405 0.01658 -0.00057" quat="-0.090901 0.708675 -0.051638 0.697746"/>
                                    <geom contype="0" mesh="upper_arm" name="geom53" rgba="0.7 0.7 0.7 1"/>
                                    <body name="l_elbow_flex_link" pos="0.4 0 0">
                                        <inertial diaginertia="0.004419 0.003965 0.003090" mass="1.90327" pos="0.01014 0.00032 -0.01211" quat="0.308784 0.646797 0.639077 0.279083"/>
                                        <joint armature="0.100000577008" axis="0 1 0" damping="1.00000128051" frictional="true" frictionloss="1.00000002114" limited="true" name="l_elbow_flex_joint" pos="0 0 0" range="-2.3213 0" stiffness="1.00000049598" type="hinge"/>
                                        <geom mesh="elbow_flex" name="geom54" rgba="0.7 0.7 0.7 1"/>
                                        <body name="l_forearm_roll_link" pos="0 0 0">
                                            <inertial diaginertia="0.01 0.01 0.01" mass="0.1" pos="0 0 0"/>
                                            <joint armature="0.10667688727" axis="1 0 0" damping="0.999271316123" frictional="true" frictionloss="0.999905165198" name="l_forearm_roll_joint" pos="0 0 0" stiffness="0.999886458745" type="hinge"/>
                                            <!--mesh name="geom55" mesh="forearm_roll_L" /-->
                                            <body name="l_forearm_link" pos="0 0 0">
                                                <inertial diaginertia="0.016633 0.015078 0.003609" mass="2.57968" pos="0.18791 -0.00017 -0.00912" quat="-0.000587 0.726286 -0.003969 0.687381"/>
                                                <geom contype="0" mesh="forearm" name="l_forearm" rgba="0.7 0.7 0.7 1"/>

                                                <!--geom name="geom56f" type="box" pos="0.22414201 0.00002379 -0.00172978" size="0.13 0.06 0.05" rgba="0.7 0.7 0.7 1" group="1"/-->

                                                <body name="l_wrist_flex_link" pos="0.321 0 0">
                                                    <inertial diaginertia="0.000653 0.000643 0.000198" mass="0.61402" pos="-0.00157 0 -0.00075" quat="0.695976 0.696411 -0.123560 0.123942"/>
                                                    <joint armature="0.100000843524" axis="0 1 0" damping="0.100001622567" frictional="true" frictionloss="1.00000005275" limited="true" name="l_wrist_flex_joint" pos="0 0 0" range="-2.094 0" stiffness="1.00000030071" type="hinge"/>
                                                    <geom contype="0" mesh="wrist_flex" name="geom57" rgba="0.7 0.7 0.7 1"/>
                                                    <body name="l_wrist_roll_link" pos="0 0 0">
                                                        <inertial diaginertia="0.01 0.01 0.01" mass="0.1" pos="0 0 0"/>
                                                        <joint armature="0.122515384966" axis="1 0 0" damping="0.0969421824172" frictional="true" frictionloss="1.00166688329" name="l_wrist_roll_joint" pos="0 0 0" stiffness="0.993714553141" type="hinge"/>
                                                        <!--mesh name="geom58" mesh="wrist_roll_L" /-->
                                                        <body childclass="gripper" name="l_gripper_palm_link" pos="0.038 0 0">
                                                            <inertial diaginertia="0.000866 0.000678 0.000351" mass="0.58007" pos="0.06623 0.00053 -0.00119" quat="-0.018184 0.706274 0.016077 0.707523"/>
                                                            <geom mesh="gripper_palm" name="geom59" pos="0 0 0" rgba="0.7 0.7 0.7 1"/>
                                                            <body name="sensor" pos="0.01 0 0">
                                                                <geom name="sensor" pos="0 0 0" quat="-0.018184 0.706274 0.016077 0.707523" rgba="0.7 0.7 0.7 1" size="0.022 0.019" type="cylinder"/>
                                                            </body>
                                                            <!--geom name="geom59f" type="capsule" pos="0.07750326 -0.00000579 -0.00000142" quat="0.49981788 0.50015276 -0.49991269 0.50011660" size="0.05263874 0.00669171" rgba="0.8 0 0 1" group="1" contype="1"/-->
                                                            <body name="l_gripper_led_frame" pos="0.0513 0 0.0244">
                                                                <inertial diaginertia="0.000000 0.000000 0.000000" mass="0.001" pos="0 0 0"/>
                                                            </body>
                                                            <body name="l_gripper_motor_accelerometer_link" pos="0 0 0">
                                                                <inertial diaginertia="0.001 0.001 0.001" mass="0.001" pos="0 0 0"/>
                                                                <geom name="geom60" pos="0 0 0" size="0.0005 0.0005 0.0005" type="box"/>
                                                            </body>
                                                            <body name="l_gripper_tool_frame" pos="0.18 0 0">

                                                            </body>
                                                                <body name="l_gripper_l_finger_link" pos="0.07691 0.01 0">
                                                                <inertial diaginertia="0.000198 0.000181 0.000077" mass="0.17126" pos="0.03598 0.0173 -0.00164" quat="0.574440 0.429111 0.518782 0.465562"/>
                                                                <!--<joint name="l_gripper_l_finger_joint" type="hinge" pos="0 0 0" axis="0 0 1" limited="true" range="0 0.548"/>-->
                                                                <geom mesh="l_finger" name="geom61" rgba="0.7 0.7 0.7 1"/>
                                                                <body name="l_gripper_l_finger_tip_link" pos="0.09137 0.00495 0">
                                                                    <inertial diaginertia="0.000015 0.000015 0.000003" mass="0.04419" pos="0.00423 0.00284 0" quat="0.249588 0.661594 -0.249588 0.661594"/>
                                                                    <!--<joint name="l_gripper_l_finger_tip_joint" type="hinge" pos="0 0 0" axis="0 0 1" limited="true" range="-.548 0"/>-->
                                                                    <geom mesh="l_finger_tip" name="l_gripper_l_finger_tip" rgba="0.7 0.7 0.7 1"/>
                                                                </body>

                                                            </body>
                                                            <body name="l_gripper_r_finger_link" pos="0.07691 -0.01 0">
                                                                <inertial diaginertia="0.000199 0.000181 0.000077" mass="0.17389" pos="0.03576 -0.01736 -0.00095" quat="0.474684 0.510909 0.446353 0.560727"/>
                                                                <!--<joint name="l_gripper_r_finger_joint" type="hinge" pos="0 0 0" axis="0 0 -1" limited="true" range="0 0.548"/>-->
                                                                <geom euler="3.14 0 0" mesh="l_finger" name="geom63" rgba="0.7 0.7 0.7 1"/>
                                                                 <site name="tip" pos="0 0 0" size="0.01"/>

                                                                <body name="l_gripper_r_finger_tip_link" pos="0.09137 -0.00495 0">
                                                                    <inertial diaginertia="0.000015 0.000015 0.000003" mass="0.04419" pos="0.00423 -0.00284 0" quat="-0.249588 0.661594 0.249588 0.661594"/>
                                                                    <!--<joint name="l_gripper_r_finger_tip_joint" type="hinge" pos="0 0 0" axis="0 0 -1" limited="true" range="-.548 0"/>-->
                                                                    <geom euler="3.14 0 0" mesh="l_finger_tip" name="l_gripper_r_finger_tip" rgba="0.7 0.7 0.7 1"/>
                                                                    <!--body name="l_gripper_l_finger_tip_frame" pos="0 0 0">
                                                                        <inertial pos="0 0 0" mass="0.001" diaginertia="0.000000 0.000000 0.000000" />
                                                                        <joint name="l_gripper_joint" type="slide" pos="0 0 0" axis="0 1 0" limited="true" range="0 0.09"/>
                                                                    </body-->

                                                                </body>

                                                        </body>

                                                        </body>
                                                    </body>
                                                </body>
                                            </body>
                                        </body>
                                    </body>
                                </body>
                            </body>
                        </body>
                    </body>

                    <body name="r_shoulder_pan_link" pos="0 -0.188 0">
                        <inertial diaginertia="0.934201 0.837701 0.242033" mass="25.799322" pos="-0.001201 0.024513 -0.098231" quat="0.927482 -0.087656 0.074060 -0.355821"/>

                        <joint axis="0 0 1" limited="true" name="r_shoulder_pan_joint" pos="0 0 0" range="-0.719 -0.718" type="hinge"/>
                        <!--joint name="r_shoulder_pan_joint" type="hinge" pos="0 0 0" axis="0 0 1" limited="true" range="-2.285398 0.714602" /-->
                        <geom contype="0" mesh="shoulder_pan" name="geom32" rgba="0.7 0.7 0.7 1"/>
                        <!--geom name="geom32f" type="capsule" pos="0.01642114 -0.00171030 -0.18118357" quat="0.69209327 0.05075781 0.04887308 0.71836061" size="0.21476608 0.19522579" rgba="0 0 0.8 1" group="1"/-->
                        <!--geom name="geom32f" type="box" pos="0.01642114 -0.00171030 -0.18118357" quat="0.69209327 0.05075781 0.04887308 0.71836061" size="0.13091806 0.18720169 0.32589236" rgba="0 0 0.8 1" group="1"/-->

                        <!--geom name="geom32f" type="box" pos="0.01642114 -0.00171030 -0.18118357" size="0.18 0.13 0.32589236" rgba="0 0 0.8 1" group="1"/-->

                        <body name="r_shoulder_lift_link" pos="0.1 0 0">
                            <inertial diaginertia="0.026187 0.020730 0.015168" mass="2.74988" pos="0.02195 -0.02664 -0.03127" quat="0.791779 0.478014 0.238985 0.295762"/>

                            <joint axis="0 1 0" limited="true" name="r_shoulder_lift_joint" pos="0 0 0" range="-0.225 -0.224" type="hinge"/>
                            <!--joint name="r_shoulder_lift_joint" type="hinge" pos="0 0 0" axis="0 1 0" limited="true" range="-0.5236 1.3963"/-->
                            <geom contype="0" mesh="shoulder_lift" name="geom33" rgba="0.7 0.7 0.7 1"/>
                            <!--<geom name="geom33f" type="capsule" pos="0.00043735 0.00010360 0.00012870" quat="0.70990818 0.03949992 0.03636729 0.70224465" size="0.14761245 0.01591613" rgba="0.7 0.7 0.7 1" group="1"/>-->
                            <body name="r_upper_arm_roll_link" pos="0 0 0">
                                <inertial diaginertia="0.01 0.01 0.01" mass="0.1" pos="0 0 0"/>

                                <!--joint name="r_upper_arm_roll_joint" type="hinge" pos="0 0 0" axis="1 0 0" limited="true" range="-3.9 0.8"/-->
                                <joint axis="1 0 0" limited="true" name="r_upper_arm_roll_joint" pos="0 0 0" range="-1.16 -1.15" type="hinge"/>
                                <!--mesh name="geom34" mesh="upper_arm_roll_L" contype="0"/-->
                                <!--geom name="geom34f" type="capsule" pos="0.12961979 -0.00000014 0" quat="1 -0.00001340 0.00000169 -0.00000728" size="0.07297432 0.00139096" group="1"/-->
                                <body name="r_upper_arm_link" pos="0 0 0">
                                    <inertial diaginertia="0.076138 0.074931 0.015133" mass="6.01769" pos="0.21398 -0.01621 -0.0002" quat="-0.045020 0.697462 -0.088537 0.709705"/>
                                    <geom contype="0" mesh="upper_arm" name="geom35" rgba="0.7 0.7 0.7 1"/>
                                    <!--geom name="geom35f" type="capsule" pos="0.21533518 0.00017574 -0.00229182" quat="0.50005025 0.49945472 0.50003903 0.50045548" size="0.09823026 0.18895381" rgba="0 0.8 0 1" group="1"/-->
                                    <body name="r_elbow_flex_link" pos="0.4 0 0">
                                        <inertial diaginertia="0.004419 0.003965 0.003090" mass="1.90327" pos="0.01014 0.00032 -0.01211" quat="0.308784 0.646797 0.639077 0.279083"/>

                                        <!--joint name="r_elbow_flex_joint" type="hinge" pos="0 0 0" axis="0 1 0" limited="true" range="-2.3213 0"/-->
                                        <joint axis="0 1 0" limited="true" name="r_elbow_flex_joint" pos="0 0 0" range="-1.052 -1.051" type="hinge"/>
                                        <geom contype="0" mesh="elbow_flex" name="geom36" rgba="0.7 0.7 0.7 1"/>
                                        <!--geom name="geom36f" type="capsule" pos="0.01080148 -0.00019654 -0.00157206" quat="0.46319936 0.53428385 0.53426711 0.46319087" size="0.08174065 0.03329964" rgba="0.7 0.7 0.7 1" group="1"/-->
                                        <body name="r_forearm_roll_link" pos="0 0 0">
                                            <inertial diaginertia="0.01 0.01 0.01" mass="0.1" pos="0 0 0"/>

                                            <!--joint name="r_forearm_roll_joint" type="hinge"   pos="0 0 0" axis="1 0 0"/-->
                                            <joint axis="1 0 0" limited="true" name="r_forearm_roll_joint" pos="0 0 0" range="36.11 36.12" type="hinge"/>
                                            <!--mesh name="geom37" mesh="forearm_roll_L" contype="0"/-->
                                            <!--geom name="geom37f" type="capsule" pos="0.04279423 -0.00004959 -0.00435061" quat="-0.00043052 0.67588833 -0.00028777 0.73700387" size="0.04187753 0.05695059" group="1"/-->
                                            <body name="r_forearm_link" pos="0 0 0">
                                                <inertial diaginertia="0.016633 0.015078 0.003609" mass="2.57968" pos="0.18791 -0.00017 -0.00912" quat="-0.000587 0.726286 -0.003969 0.687381"/>
                                                <geom contype="0" mesh="forearm" name="r_forearm" rgba="0.7 0.7 0.7 1"/>
                                                <!--geom name="geom38f" type="capsule" pos="0.22414201 -0.00002379 -0.00172978" quat="0.00011562 0.73364272 -0.00009110 0.67953538" size="0.06893772 0.10796238" rgba="0.7 0.7 0.7 1" group="1"/-->

                                                <!--geom name="geom38f" type="box" pos="0.22414201 -0.00002379 -0.00172978" size="0.13 0.06 0.05" rgba="0.7 0.7 0.7 1" group="1"/-->

                                                <body name="r_wrist_flex_link" pos="0.321 0 0">
                                                    <inertial diaginertia="0.000653 0.000643 0.000198" mass="0.61402" pos="-0.00157 0 -0.00075" quat="0.695976 0.696411 -0.123560 0.123942"/>

                                                    <!--joint name="r_wrist_flex_joint" type="hinge" pos="0 0 0" axis="0 1 0" limited="true" range="-2.094 0"/-->
                                                    <joint axis="0 1 0" limited="true" name="r_wrist_flex_joint" pos="0 0 0" range="-1.821 -1.820" type="hinge"/>
                                                    <geom contype="0" mesh="wrist_flex" name="geom39" rgba="0.7 0.7 0.7 1"/>
                                                    <!--geom name="geom39f" type="capsule" pos="-0.00166503 -0.00000018 -0.00367085" quat="0.70247354 -0.08138660 -0.08143754 0.70233544" size="0.03978695 0.01715654" rgba="0.7 0.7 0.7 1" group="1"/-->
                                                    <body name="r_wrist_roll_link" pos="0 0 0">
                                                        <inertial diaginertia="0.01 0.01 0.01" mass="0.1" pos="0 0 0"/>

                                                        <!--joint name="r_wrist_roll_joint" type="hinge"   pos="0 0 0" axis="1 0 0"/-->
                                                        <joint axis="1 0 0" limited="true" name="r_wrist_roll_joint" pos="0 0 0" range="-78.67 -78.66" type="hinge"/>
                                                        <!--mesh name="geom40" mesh="wrist_roll_L" contype="0"/-->
                                                        <!--geom name="geom40f" type="capsule" pos="0.03324894 0.00005320 -0.00012423" quat="0.67531716 0.73752742 -0.00019246 0.00000483" size="0.02078140 0.00071779" group="1"/-->
                                                        <body childclass="gripper" name="r_gripper_palm_link" pos="0 0 0">
                                                            <inertial diaginertia="0.000866 0.000678 0.000351" mass="0.58007" pos="0.06623 0.00053 -0.00119" quat="-0.018184 0.706274 0.016077 0.707523"/>
                                                            <geom contype="0" mesh="gripper_palm" name="geom41" rgba="0.7 0.7 0.7 1"/>
                                                            <!--geom name="geom41f" type="capsule" pos="0.07750326 0.00000579 -0.00000142" quat="0.49981788 0.50015276 -0.49991269 0.50011660" size="0.05263874 0.00669171" rgba="0.8 0 0 1" group="1"/-->
                                                            <!--geom name="geom41f" type="box" pos="0.07750326 0.00000579 -0.00000142" quat="0.49981788 0.50015276 -0.49991269 0.50011660" size="0.02425377 0.048 0.05" rgba="0.8 0 0 1" group="1"/-->
                                                            <!--body name="r_gripper_led_frame" pos="0.0513 0 0.0244">
                                                                <inertial pos="0 0 0" mass="0.001" diaginertia="0.000000 0.000000 0.000000" />
                                                            </body>
                                                            <body name="r_gripper_motor_accelerometer_link" pos="0 0 0">
                                                                <inertial pos="0 0 0" mass="0.001" diaginertia="0.001 0.001 0.001" />
                                                                <geom name="geom42" type="box" pos="0 0 0" size="0.0005 0.0005 0.0005" />
                                                            </body>-->
                                                            <body name="r_gripper_tool_frame" pos="0.18 0 0">
                                                                <inertial diaginertia="0.000000 0.000000 0.000000" mass="0.001" pos="0 0 0"/>

                                                            </body>
                                                            <body name="r_gripper_l_finger_link" pos="0.07691 0.01 0">
                                                                <inertial diaginertia="0.000198 0.000181 0.000077" mass="0.17126" pos="0.03598 0.0173 -0.00164" quat="0.574440 0.429111 0.518782 0.465562"/>
                                                                <!--<joint name="r_gripper_l_finger_joint" type="hinge" pos="0 0 0" axis="0 0 1" limited="true" range="0 0.548"/>-->
                                                                <geom mesh="l_finger" name="geom43" rgba="0.7 0.7 0.7 1"/>
                                                                <body name="r_gripper_l_finger_tip_link" pos="0.09137 0.00495 0">
                                                                    <inertial diaginertia="0.000015 0.000015 0.000003" mass="0.04419" pos="0.00423 0.00284 0" quat="0.249588 0.661594 -0.249588 0.661594"/>
                                                                    <!--<joint name="r_gripper_l_finger_tip_joint" type="hinge" pos="0 0 0" axis="0 0 1" limited="true" range="-.548 0"/>-->
                                                                    <geom mesh="l_finger_tip" name="r_gripper_l_finger_tip" rgba="0.7 0.7 0.7 1"/>
                                                                </body>
                                                            </body>
                                                            <body name="r_gripper_r_finger_link" pos="0.07691 -0.01 0">
                                                                <inertial diaginertia="0.000199 0.000181 0.000077" mass="0.17389" pos="0.03576 -0.01736 -0.00095" quat="0.474684 0.510909 0.446353 0.560727"/>
                                                                <!--<joint name="r_gripper_r_finger_joint" type="hinge" pos="0 0 0" axis="0 0 -1" limited="true" range="0 .548"/>-->
                                                                <geom euler="3.14 0 0" mesh="l_finger" name="geom45" rgba="0.7 0.7 0.7 1"/>
                                                                <body name="r_gripper_r_finger_tip_link" pos="0.09137 -0.00495 0">
                                                                    <inertial diaginertia="0.000015 0.000015 0.000003" mass="0.04419" pos="0.00423 -0.00284 0" quat="-0.249588 0.661594 0.249588 0.661594"/>
                                                                    <!--<joint name="r_gripper_r_finger_tip_joint" type="hinge" pos="0 0 0" axis="0 0 -1" limited="true" range="-.548 0"/>-->
                                                                    <geom euler="3.14 0 0" mesh="l_finger_tip" name="r_gripper_r_finger_tip" rgba="0.7 0.7 0.7 1"/>
                                                                    <!--body name="r_gripper_l_finger_tip_frame" pos="0 0 0">
                                                                        <inertial pos="0 0 0" mass="0.001" diaginertia="0.000000 0.000000 0.000000" />
                                                                        <joint name="r_gripper_joint" type="slide" pos="0 0 0" axis="0 1 0" limited="true" range="0 0.09" maxvel="0.2" />
                                                                    </body-->
                                                                </body>
                                                            </body>
                                                            <!--body name="r_gripper_l_parallel_link" pos="0.05891 0.031 0">
                                                                <inertial pos="0.03598 0.0173 -0.00164" quat="0.574440 0.429111 0.518782 0.465562" mass="0.17126" diaginertia="0.000198 0.000181 0.000077" />
                                                                <joint name="r_gripper_l_parallel_root_joint" type="hinge" pos="0 0 0" axis="0 0 1" limited="true" range="0 0.548"/>
                                                                <geom name="geom47" type="box" pos="0.045747 0 0" quat="0.999634 0 0 0.027058" size="0.045747 0.0025 0.0025" />
                                                            </body>
                                                            <body name="r_gripper_r_parallel_link" pos="0.05891 -0.031 0">
                                                                <inertial pos="0.03576 -0.01736 -0.00095" quat="0.474684 0.510909 0.446353 0.560727" mass="0.17389" diaginertia="0.000199 0.000181 0.000077" />
                                                                <joint name="r_gripper_r_parallel_root_joint" type="hinge" pos="0 0 0" axis="0 0 -1" limited="true" range="0 0.548"/>
                                                                <geom name="geom48" type="box" pos="0.045747 0 0" quat="0.999634 0 0 -0.027058" size="0.045747 0.0025 0.0025" />
                                                            </body-->
                                                        </body>
                                                    </body>
                                                </body>
                                            </body>
                                            <!--body name="r_forearm_cam_frame" pos="0.135 0 0.044" quat="0.679288 0.679288 0.196387 0.196387">
                                                <inertial pos="0 0 0" mass="0.01" diaginertia="0.001 0.001 0.001" />
                                                <geom name="geom49" type="box" pos="0 0 0" size="0.005 0.005 0.005" />
                                                <body name="r_forearm_cam_optical_frame" pos="0 0 0" quat="0.5 -0.5 -0.5 -0.5">
                                                    <inertial pos="0 0 0" mass="0.001" diaginertia="0.000000 0.000000 0.000000" />
                                                </body>
                                            </body-->
                                        </body>
                                    </body>
                                </body>
                            </body>
                        </body>
                    </body>
                </body>

            </body>
        </body>
    </worldbody>
<actuator>
    <motor ctrllimited="true" ctrlrange="-3.0 3.0" joint="l_shoulder_pan_joint"/>
    <motor ctrllimited="true" ctrlrange="-3.0 3.0" joint="l_shoulder_lift_joint"/>
    <motor ctrllimited="true" ctrlrange="-3.0 3.0" joint="l_upper_arm_roll_joint"/>
    <motor ctrllimited="true" ctrlrange="-3.0 3.0" joint="l_elbow_flex_joint"/>
    <motor ctrllimited="true" ctrlrange="-3.0 3.0" joint="l_forearm_roll_joint"/>
    <motor ctrllimited="true" ctrlrange="-3.0 3.0" joint="l_wrist_flex_joint"/>
    <motor ctrllimited="true" ctrlrange="-3.0 3.0" joint="l_wrist_roll_joint"/>
    <!--general site="lego_target" gear="0 0 -1 0 0 0" dynprm="0 0 0" gainprm="0 0 0" biastype="affine" biasprm="0.981 0 0"/-->
</actuator>



    <!--actuator>
        <motor joint="l_shoulder_pan_joint" ctrlrange="-30.0 30.0" ctrllimited="true" forcerange="-30.0 30.0" forcelimited="true"/>
        <motor joint="l_shoulder_lift_joint" ctrlrange="-30.0 30.0" ctrllimited="true" forcerange="-30.0 30.0" forcelimited="true" />
        <motor joint="l_upper_arm_roll_joint" ctrlrange="-30.0 30.0" ctrllimited="true" forcerange="-30.0 30.0" forcelimited="true" />
        <motor joint="l_elbow_flex_joint" ctrlrange="-30.0 30.0" ctrllimited="true" forcerange="-30.0 30.0" forcelimited="true" />
        <motor joint="l_forearm_roll_joint" ctrlrange="-30.0 30.0" ctrllimited="true" forcerange="-30.0 30.0" forcelimited="true" />
        <motor joint="l_wrist_flex_joint" ctrlrange="-30.0 30.0" ctrllimited="true" forcerange="-30.0 30.0" forcelimited="true" />
        <motor joint="l_wrist_roll_joint" ctrlrange="-30.0 30.0" ctrllimited="true" forcerange="-30.0 30.0" forcelimited="true" />
    </actuator-->
    <!--actuator>
        <velocity joint="l_shoulder_pan_joint" ctrlrange="-2.088 2.088" ctrllimited="true"/>
        <velocity joint="l_shoulder_lift_joint" ctrlrange="-2.082 2.082" ctrllimited="true"/>
        <velocity joint="l_upper_arm_roll_joint" ctrlrange="-3.27 3.27" ctrllimited="true"/>
        <velocity joint="l_elbow_flex_joint" ctrlrange="-3.3 3.3" ctrllimited="true"/>
        <velocity joint="l_forearm_roll_joint" ctrlrange="-3.6 3.6" ctrllimited="true"/>
        <velocity joint="l_wrist_flex_joint" ctrlrange="-3.078 3.078" ctrllimited="true"/>
        <velocity joint="l_wrist_roll_joint" ctrlrange="-3.6 3.6" ctrllimited="true"/>
    </actuator-->
</mujoco><!--<motor joint="l_wrist_flex_joint" ctrlrange="-3.0 3.0" ctrllimited="true"  />
<motor joint="l_wrist_roll_joint" ctrlrange="-3.0 3.0" ctrllimited="true"  />-->