<!-- Cartpole Model

    The state space is populated with joints in the order that they are
    defined in this file. The actuators also operate on joints.

    State-Space (name/joint/parameter):
        - cart      slider      position (m)
        - pole      hinge       angle (rad)
        - cart      slider      velocity (m/s)
        - pole      hinge       angular velocity (rad/s)

    Actuators (name/actuator/parameter):
        - cart      motor       force x (N)

-->
<mujoco model='cartpole'>
    <compiler uniquevertex='false'
              inertiafromgeom='true'
              coordinate='local'/>

    <default>
        <joint damping='0.05'
               makeactuator='false' />
        <geom contype='0'
              friction='1 0.1 0.1'
              rgba='0.7 0.7 0 1' />
    </default>

    <option timestep='0.02'
            gravity='1e-5 0 -9.81' />

    <size nstack='3000'/>

    <body>
        <geom name='floor'
              pos='0 0 -3.0'
              size='40 40 40'
              type='plane'
              rgba='0.8 0.9 0.8 1' />
        <geom name='rail'
              type='capsule'
              pos='0 0 0'
              quat='0.707 0 0.707 0'
              size='0.02 1'
              rgba='0.3 0.3 0.7 1' />
        <body name='cart' pos='0 0 0'>
            <joint name='slider'
                   type='slide'
                   islimited='true'
                   pos='0 0 0'
                   axis='1 0 0'
                   range='-1 1'
                   mindist='0.01'/>
            <geom name='cart'
                  type='capsule'
                  pos='0 0 0'
                  quat='0.707 0 0.707 0'
                  size='0.1 0.1' />
            <body name='pole' pos='0 0 0'>
                <joint name='hinge'
                       type='hinge'
                       pos='0 0 0'
                       axis='0 1 0'/>
                <geom name='cpole'
                      type='capsule'
                      fromto='0 0 0 0 0 0.6'
                      size='0.045 0.3'
                      rgba='0 0.7 0.7 1' />
                <site name='tip'
                      pos='.001 0 .6'/>
            </body>
        </body>
    </body>

    <actuator>
        <motor name='slide'
               joint='slider'
               gear='100'
               ctrlrange='-.5 .5'
               isctrllimited='true'/>
    </actuator>
</mujoco>

