<mujoco model="gripper">
  <option gravity="0 0 0"/>
  <asset>
    <texture name="texgeom" type="cube" builtin="flat" mark="cross" width="127" height="1278"
        rgb1="0.8 0.6 0.4" rgb2="0.8 0.6 0.4" markrgb="1 1 1" random="0.01"/>  
    <material name='geom' texture="texgeom" texuniform="true"/>
  </asset>
  <default>
    <joint limited='true' damping='1' armature='0' />
    <geom contype='1' conaffinity='1' condim='1' rgba='0.8 0.6 .4 1' 
        margin="0.001" solref=".02 1" solimp=".8 .8 .01" material="geom"/>
  </default>
  <worldbody>
    <body name="root" pos="0 0 0">
      <joint name="root_joint" type="hinge" axis="0 1 0" pos="0 0 0" limited="false" />
      <geom name="link1" type="capsule" fromto="0 0 0 0.707 0 0.707" size="0.05" friction="0.9" />
      <body name="child1" pos="0.707 0 0.707">
        <joint name="child1_joint" type="hinge" axis="0 1 0" pos="0 0 0" range="-120 120"/>
        <geom name="link2" type="capsule" fromto="0 0 0 0.707 0 0.707" size="0.05" friction="0.9" />
      </body>
    </body>
  </worldbody>
  <actuator>
    <motor joint="root_joint" ctrlrange="-100.0 100.0" ctrllimited="true"/>
    <motor joint="child1_joint" ctrlrange="-100.0 100.0" ctrllimited="true"/>
  </actuator>

</mujoco>
