<mujoco model="multilink_reacher">
  <compiler angle="radian" inertiafromgeom="true"/>
  <default>
    <joint armature="1" damping="10" limited="true"/>
    <geom contype="0" friction="1 0.1 0.1" rgba="0.7 0.7 0 1"/>
  </default>
  <option gravity="0 0 0" integrator="RK4" timestep="0.01"/>
  <worldbody>
    <body name="link_0" pos="0 0 0">
      <joint limited="false" name="link_0_ball" pos="0 0 0" type="ball"/>
      <geom fromto="0 0 0 0.1 0 0" name="link_0_geom" rgba="0.0 0.4 0.6 1" size=".01" type="capsule"/>
      <body name="link_1" pos="0.10 0 0">
        <joint limited="false" name="link_1_ball" pos="0 0 0" type="ball"/>
        <geom fromto="0 0 0 0.1 0 0" name="link_1_geom" rgba="0.0 0.4 0.6 1" size=".01" type="capsule"/>
        <body name="link_2" pos="0.10 0 0">
          <joint limited="false" name="link_2_ball" pos="0 0 0" type="ball"/>
          <geom fromto="0 0 0 0.1 0 0" name="link_2_geom" rgba="0.0 0.4 0.6 1" size=".01" type="capsule"/>
          <body name="link_3" pos="0.10 0 0">
            <joint limited="false" name="link_3_ball" pos="0 0 0" type="ball"/>
            <geom fromto="0 0 0 0.1 0 0" name="link_3_geom" rgba="0.0 0.4 0.6 1" size=".01" type="capsule"/>
            <body name="fingertip" pos="0.11 0 0">
              <geom contype="0" name="fingertip" pos="0 0 0" rgba="0.0 0.8 0.6 1" size=".01" type="sphere"/>
            </body>
          </body>
        </body>
      </body>
    </body>
    <body name="target" pos="0.1 -0.1 0.01">
      <joint armature="0" axis="1 0 0" damping="0" limited="true" name="target_x" pos="0 0 0" range="-.27 .27" ref="-.1" stiffness="0" type="slide"/>
      <joint armature="0" axis="0 1 0" damping="0" limited="true" name="target_y" pos="0 0 0" range="-.27 .27" ref="-.1" stiffness="0" type="slide"/>
      <joint armature="0" axis="0 0 1" damping="0" limited="true" name="target_z" pos="0 0 0" range="-.27 .27" ref="-.1" stiffness="0" type="slide"/>
      <geom conaffinity="0" contype="0" name="target" pos="0 0 0" rgba="0.9 0.2 0.2 1" size=".009" type="sphere"/>
    </body>
  </worldbody>
  <actuator>
    <motor ctrllimited="true" ctrlrange="-1.0 1.0" gear="200 0 0" joint="link_0_ball"/>
    <motor ctrllimited="true" ctrlrange="-1.0 1.0" gear="0 200 0" joint="link_0_ball"/>
    <motor ctrllimited="true" ctrlrange="-1.0 1.0" gear="0 0 200" joint="link_0_ball"/>
    <motor ctrllimited="true" ctrlrange="-1.0 1.0" gear="200 0 0" joint="link_1_ball"/>
    <motor ctrllimited="true" ctrlrange="-1.0 1.0" gear="0 200 0" joint="link_1_ball"/>
    <motor ctrllimited="true" ctrlrange="-1.0 1.0" gear="0 0 200" joint="link_1_ball"/>
    <motor ctrllimited="true" ctrlrange="-1.0 1.0" gear="200 0 0" joint="link_2_ball"/>
    <motor ctrllimited="true" ctrlrange="-1.0 1.0" gear="0 200 0" joint="link_2_ball"/>
    <motor ctrllimited="true" ctrlrange="-1.0 1.0" gear="0 0 200" joint="link_2_ball"/>
    <motor ctrllimited="true" ctrlrange="-1.0 1.0" gear="200 0 0" joint="link_3_ball"/>
    <motor ctrllimited="true" ctrlrange="-1.0 1.0" gear="0 200 0" joint="link_3_ball"/>
    <motor ctrllimited="true" ctrlrange="-1.0 1.0" gear="0 0 200" joint="link_3_ball"/>
  </actuator>
</mujoco>
